#priority 6
import crafttweaker.block.IBlockState;
import crafttweaker.item.IIngredient;
import crafttweaker.item.IItemStack;
import crafttweaker.world.IBlockPos;
import crafttweaker.world.IFacing;
import crafttweaker.world.IWorld;
import mods.contenttweaker.Random;
import mods.contenttweaker.World;
import mods.gregtech.IControllerTile;
import mods.gregtech.multiblock.Builder;
import mods.gregtech.multiblock.CTPredicate;
import mods.gregtech.multiblock.FactoryBlockPattern;
import mods.gregtech.multiblock.IPatternMatchContext;
import mods.gregtech.multiblock.functions.ICheckRecipeFunction;
import mods.gregtech.multiblock.functions.IPatternBuilderFunction;
import mods.gregtech.multiblock.functions.IUpdateFormedValidFunction;
import mods.gregtech.multiblock.functions.IFormStructureFunction;
import mods.gregtech.multiblock.IBlockPattern;
import mods.gregtech.multiblock.RelativeDirection;
import mods.gregtech.recipe.FactoryRecipeMap;
import mods.gregtech.recipe.functions.ICompleteRecipeFunction;
import mods.gregtech.recipe.IRecipe;
import mods.gregtech.recipe.IRecipeLogic;
import mods.gregtech.recipe.RecipeMap;

var loc = "mbt:space_elevator";

val space_elevator = Builder.start(loc, 3000)
    .withPattern(function(controller as IControllerTile) as IBlockPattern {
                       return FactoryBlockPattern.start(RelativeDirection.RIGHT, RelativeDirection.DOWN, RelativeDirection.FRONT)
                .aisle("                                   ", "                                   ", "                                   ", "                                   ", "                                   ", "                                   ", "                                   ", "                                   ", "                                   ", "                                   ", "                                   ", "                                   ", "                                   ", "                                   ", "                                   ", "                                   ", "                                   ", "                                   ", "                                   ", "                                   ", "                                   ", "                                   ", "                                   ", "                                   ", "                                   ", "                                   ", "                                   ", "                                   ", "                                   ", "                                   ", "                                   ", "                                   ", "                                   ", "                                   ", "                                   ", "                                   ", "                                   ", "                                   ", "                                   ", "                                   ", "                                   ", "               FF FF               ", "               AAAAA               ")
                .aisle("                                   ", "                                   ", "                                   ", "                                   ", "                                   ", "                                   ", "                                   ", "                                   ", "                                   ", "                                   ", "                                   ", "                                   ", "                                   ", "                                   ", "                                   ", "                                   ", "                                   ", "                                   ", "                                   ", "                                   ", "                                   ", "                                   ", "                                   ", "                                   ", "                                   ", "                                   ", "                                   ", "                                   ", "                                   ", "                                   ", "                                   ", "                                   ", "                                   ", "                                   ", "                                   ", "                                   ", "                                   ", "                                   ", "                                   ", "                                   ", "               D   D               ", "            FFFFF FFFFF            ", "            AAAAAAAAAAA            ")
                .aisle("                                   ", "                                   ", "                                   ", "                                   ", "                                   ", "                                   ", "                                   ", "                                   ", "                                   ", "                                   ", "                                   ", "                                   ", "                                   ", "                                   ", "                                   ", "                                   ", "                                   ", "                                   ", "                                   ", "                                   ", "                                   ", "                                   ", "                                   ", "                                   ", "                                   ", "                                   ", "                                   ", "                                   ", "                                   ", "                                   ", "                                   ", "                                   ", "                                   ", "                                   ", "                                   ", "                                   ", "                                   ", "                                   ", "                                   ", "                                   ", "            DDDDE EDDDD            ", "          FFFFFFF FFFFFFF          ", "          AAAAAAAAAAAAAAA          ")
                .aisle("                                   ", "                                   ", "                                   ", "                                   ", "                                   ", "                                   ", "                                   ", "                                   ", "                                   ", "                                   ", "                                   ", "                                   ", "                                   ", "                                   ", "                                   ", "                                   ", "                                   ", "                                   ", "                                   ", "                                   ", "                                   ", "                                   ", "                                   ", "                                   ", "                                   ", "                                   ", "                                   ", "                                   ", "                                   ", "                                   ", "                                   ", "                                   ", "                                   ", "                                   ", "                                   ", "                                   ", "                                   ", "                                   ", "                                   ", "                E E                ", "          DD   DE ED   DD          ", "         FFFFFFD   DFFFFFF         ", "        AAAAAAAAAAAAAAAAAAA        ")
                .aisle("                                   ", "                                   ", "                                   ", "                                   ", "                                   ", "                                   ", "                                   ", "                                   ", "                                   ", "                                   ", "                                   ", "                                   ", "                                   ", "                                   ", "                                   ", "                                   ", "                                   ", "                                   ", "                                   ", "                                   ", "                                   ", "                                   ", "                                   ", "                                   ", "                                   ", "                                   ", "                                   ", "                                   ", "                                   ", "                                   ", "                                   ", "                                   ", "                                   ", "                                   ", "                                   ", "                                   ", "                                   ", "                                   ", "                E E                ", "               DE ED               ", "               D   D               ", "         FFF           FFF         ", "       AAAAAAAAAAAAAAAAAAAAA       ")
                .aisle("                                   ", "                                   ", "                                   ", "                                   ", "                                   ", "                                   ", "                                   ", "                                   ", "                                   ", "                                   ", "                                   ", "                                   ", "                                   ", "                                   ", "                                   ", "                                   ", "                                   ", "                                   ", "                                   ", "                                   ", "                                   ", "                                   ", "                                   ", "                                   ", "                                   ", "                                   ", "                                   ", "                                   ", "                                   ", "                                   ", "                                   ", "                                   ", "                                   ", "                                   ", "                                   ", "                                   ", "                                   ", "                E E                ", "               DE ED               ", "               DE ED               ", "                                   ", "                                   ", "      AAAAAAAAAAAAAAAAAAAAAAA      ")
                .aisle("                                   ", "                                   ", "                                   ", "                                   ", "                                   ", "                                   ", "                                   ", "                                   ", "                                   ", "                                   ", "                                   ", "                                   ", "                                   ", "                                   ", "                                   ", "                                   ", "                                   ", "                                   ", "                                   ", "                                   ", "                                   ", "                                   ", "                                   ", "                                   ", "                                   ", "                                   ", "                                   ", "                                   ", "                                   ", "                                   ", "                                   ", "                                   ", "                                   ", "                                   ", "                                   ", "                E E                ", "               DE ED               ", "               DE ED               ", "               DE ED               ", "                                   ", "                                   ", "                                   ", "     AAAAAAAAAAAAAAAAAAAAAAAAA     ")
                .aisle("                                   ", "                                   ", "                                   ", "                                   ", "                                   ", "                                   ", "                                   ", "                                   ", "                                   ", "                                   ", "                                   ", "                                   ", "                                   ", "                                   ", "                                   ", "                                   ", "                                   ", "                                   ", "                                   ", "                                   ", "                                   ", "                                   ", "                                   ", "                                   ", "                                   ", "                                   ", "                                   ", "                                   ", "                                   ", "                                   ", "                                   ", "                                   ", "                E E                ", "              HDE EDH              ", "               DE ED               ", "               DE ED               ", "               DE ED               ", "                                   ", "                                   ", "                                   ", "                                   ", "                                   ", "    AAAAAAAAAAAAAAAAAAAAAAAAAAA    ")
                .aisle("                                   ", "                                   ", "                                   ", "                                   ", "                                   ", "                                   ", "                                   ", "                                   ", "                                   ", "                                   ", "                                   ", "                                   ", "                                   ", "                                   ", "                                   ", "                                   ", "                                   ", "                                   ", "                                   ", "                                   ", "                                   ", "                                   ", "                                   ", "                                   ", "                                   ", "                                   ", "                                   ", "                                   ", "                                   ", "                E E                ", "               DE ED               ", "               DE ED               ", "               DE ED               ", "            HH DE ED HH            ", "                                   ", "                                   ", "                                   ", "                                   ", "               X X X               ", "               X X X               ", "               X X X               ", "               X X X               ", "   AAAAAAAAAAAAX X XAAAAAAAAAAAA   ")
                .aisle("                                   ", "                                   ", "                                   ", "                                   ", "                                   ", "                                   ", "                                   ", "                                   ", "                                   ", "                                   ", "                                   ", "                                   ", "                                   ", "                                   ", "                                   ", "                                   ", "                                   ", "                                   ", "                                   ", "                                   ", "                                   ", "                                   ", "                                   ", "                                   ", "                                   ", "                                   ", "                E E                ", "               DE ED               ", "               DE ED               ", "               DE ED               ", "               DE ED               ", "                                   ", "         E               E         ", "         EHH           HHE         ", "         E               E         ", "         E               E         ", "         E               E         ", "         E               E         ", "         E     X X X     E         ", "         E     I I I     E         ", "         E     X X X     E         ", "   FF    E     X X X     E    FF   ", "   AAAAAAAAAAAAX X XAAAAAAAAAAAA   ")
                .aisle("                                   ", "                                   ", "                                   ", "                                   ", "                                   ", "                                   ", "                                   ", "                                   ", "                                   ", "                                   ", "                                   ", "                                   ", "                                   ", "                                   ", "                                   ", "                                   ", "                                   ", "                                   ", "                                   ", "                                   ", "                                   ", "                                   ", "                E E                ", "               DE ED               ", "               DE ED               ", "               DE ED               ", "               DE ED               ", "               DE ED               ", "          E             E          ", "          E             E          ", "          E             E          ", "          E             E          ", "          E             E          ", "         HE             EH         ", "                                   ", "                                   ", "                                   ", "                                   ", "                                   ", "                                   ", "   D                           D   ", "  FFF          F F F          FFF  ", "  AAAAAAAAAAAAA     AAAAAAAAAAAAA  ")
                .aisle("                                   ", "                                   ", "                                   ", "                                   ", "                                   ", "                                   ", "                                   ", "                                   ", "                                   ", "                                   ", "                                   ", "                                   ", "                                   ", "                                   ", "                E E                ", "               DE ED               ", "               DE ED               ", "               DE ED               ", "               DE ED               ", "               DE ED               ", "               DE ED               ", "               DE ED               ", "               DE ED               ", "               DE ED               ", "                                   ", "                                   ", "           E           E           ", "           E           E           ", "           E           E           ", "           E           E           ", "           E           E           ", "                                   ", "                                   ", "         H               H         ", "                                   ", "                                   ", "                                   ", "                                   ", "                                   ", "                                   ", "   D                           D   ", "  FFF          F F F          FFF  ", "  AAAAAAAAAAAAA     AAAAAAAAAAAAA  ")
                .aisle("                                   ", "                                   ", "                                   ", "                                   ", "                                   ", "                                   ", "                                   ", "                E E                ", "               DE ED               ", "               DE ED               ", "               DE ED               ", "               DE ED               ", "               DE ED               ", "               DE ED               ", "               DE ED               ", "               DE ED               ", "                                   ", "                                   ", "                                   ", "                                   ", "                                   ", "             HH     HH             ", "            E         E            ", "            E         E            ", "            E         E            ", "            E         E            ", "            E         E            ", "            E         E            ", "                                   ", "                                   ", "                                   ", "                                   ", "                                   ", "        H                 H        ", "                                   ", "                                   ", "                                   ", "                                   ", "                                   ", "                                   ", "  D                             D  ", " FFF          FFFFFFF          FFF ", " AAAAAAAAAAAAAAAAAAAAAAAAAAAAAAAAA ")
                .aisle("                                   ", "                                   ", "                                   ", "                                   ", "                                   ", "                                   ", "                FFF                ", "                                   ", "                                   ", "                                   ", "                                   ", "                                   ", "                                   ", "                                   ", "             E       E             ", "             E       E             ", "             E       E             ", "             E       E             ", "             E       E             ", "             E       E             ", "             E       E             ", "            HE       EH            ", "             E       E             ", "             E       E             ", "                                   ", "                                   ", "                                   ", "                                   ", "                                   ", "                                   ", "                                   ", "                                   ", "                                   ", "        H                 H        ", "                                   ", "                                   ", "                                   ", "                                   ", "                                   ", "                                   ", "  D                             D  ", " FFF         FFFFFFFFF         FFF ", " AAAAAAAAAAAAAAAAAAAAAAAAAAAAAAAAA ")
                .aisle("                FFF                ", "                 E                 ", "                 E                 ", "                 E                 ", "                 E                 ", "                 E                 ", "               F   F               ", "              E     E              ", "              E     E              ", "              E     E              ", "              E     E              ", "              E     E              ", "              E     E              ", "              E     E              ", "              E     E              ", "              E     E              ", "                                   ", "                                   ", "                FFF                ", "                                   ", "                                   ", "            H         H            ", "                                   ", "                                   ", "                                   ", "                                   ", "                                   ", "                                   ", "                FFF                ", "                                   ", "                                   ", "                                   ", "                                   ", "       H                   H       ", "                                   ", "                                   ", "                                   ", "                                   ", "                XXX                ", "                X~X                ", "  D             XXX             D  ", " FFF        FFFFFFFFFFF        FFF ", " AAAAAAAAAAAAAAAAAAAAAAAAAAAAAAAAA ")
                .aisle("               F D F               ", "                 D                 ", "                 D                 ", "                 D                 ", "                 D                 ", "                 D                 ", "              F  D  F              ", "                 D                 ", "            D    D    D            ", "            D    D    D            ", "            D    D    D            ", "            D    D    D            ", "            D    D    D            ", "            D    D    D            ", "            D    D    D            ", "           DD    D    DD           ", "           D     D     D           ", "           D     D     D           ", "           D   F D F   D           ", "           D     C     D           ", "           D     C     D           ", "           D     C     D           ", "           D     C     D           ", "          DD     C     DD          ", "          D      C      D          ", "          D      C      D          ", "          D      C      D          ", "         DD      C      DD         ", "         D     FDCDF     D         ", "         D      DCD      D         ", "        DD      DCD      DD        ", "        D       DCD       D        ", "        D       DCD       D        ", "       DD      DDCDD      DD       ", "       D       D C D       D       ", "       D       D C D       D       ", "      DD       D C D       DD      ", "      D        D C D        D      ", "     DD XX     XDCDX     XX DD     ", "    DD  XI     XDCDX     IX  DD    ", " DDDD   XX     XDCDX     XX   DDDD ", "FFFD    XXFFFFFDDDDDFFFFFXX    DFFF", "AAAAAAAAXX  AAAXXXXXAAA  XXAAAAAAAA")
                .aisle("              F     F              ", "                                   ", "                                   ", "                                   ", "                                   ", "                                   ", "             F       F             ", "            E         E            ", "            E         E            ", "            E         E            ", "            E         E            ", "            E         E            ", "            E         E            ", "            E         E            ", "           EE         EE           ", "           EE         EE           ", "           E           E           ", "           E           E           ", "           E  F     F  E           ", "           E           E           ", "           E           E           ", "           E           E           ", "          EE           EE          ", "          EE           EE          ", "          E             E          ", "          E             E          ", "         EE             EE         ", "         EE             EE         ", "         E    FD   DF    E         ", "        EE     D   D     EE        ", "        EE     D   D     EE        ", "        E      D   D      E        ", "       EE      D   D      EE       ", "       EE      D   D      EE       ", "       E                   E       ", "      EE                   EE      ", "      EE                   EE      ", "     EE                     EE     ", "    EEE       XD   DX       EEE    ", "   EEE        XD   DX        EEE   ", "  EE          XD   DX          EE  ", "FFF         FFFDDDDDFFF         FFF", "AAAAAAAA    AAAXXXXXAAA    AAAAAAAA")
                .aisle("              FD   DF              ", "              ED   DE              ", "              ED   DE              ", "              ED   DE              ", "              ED   DE              ", "              ED   DE              ", "             F D   D F             ", "               D   D               ", "               D   D               ", "               D   D               ", "               D   D               ", "               D   D               ", "               D   D               ", "               D   D               ", "               D   D               ", "               D   D               ", "               D - D               ", "               D - D               ", "              FD - DF              ", "               C - C               ", "               C - C               ", "               C - C               ", "               C - C               ", "               C - C               ", "               C - C               ", "               C - C               ", "               C - C               ", "               C - C               ", "              FC - CF              ", "               C - C               ", "               C - C               ", "               C - C               ", "               C - C               ", "               C - C               ", "               C - C               ", "               C - C               ", "               C - C               ", "               C - C               ", "        XX    XC - CX    XX        ", "        XI    XC - CX    IX        ", "        XX    XC - CX    XX        ", "        XXFFFFFDDDDDFFFFFXX        ", "AAAAAAAAXX  AAAXXXXXAAA  XXAAAAAAAA")
                .aisle("              F     F              ", "                                   ", "                                   ", "                                   ", "                                   ", "                                   ", "             F       F             ", "            E         E            ", "            E         E            ", "            E         E            ", "            E         E            ", "            E         E            ", "            E         E            ", "            E         E            ", "           EE         EE           ", "           EE         EE           ", "           E           E           ", "           E           E           ", "           E  F     F  E           ", "           E           E           ", "           E           E           ", "           E           E           ", "          EE           EE          ", "          EE           EE          ", "          E             E          ", "          E             E          ", "         EE             EE         ", "         EE             EE         ", "         E    FD   DF    E         ", "        EE     D   D     EE        ", "        EE     D   D     EE        ", "        E      D   D      E        ", "       EE      D   D      EE       ", "       EE      D   D      EE       ", "       E                   E       ", "      EE                   EE      ", "      EE                   EE      ", "     EE                     EE     ", "    EEE       XD   DX       EEE    ", "   EEE        XD   DX        EEE   ", "  EE          XD   DX          EE  ", "FFF         FFFDDDDDFFF         FFF", "AAAAAAAA    AAAXXXXXAAA    AAAAAAAA")
                .aisle("               F D F               ", "                 D                 ", "                 D                 ", "                 D                 ", "                 D                 ", "                 D                 ", "              F  D  F              ", "                 D                 ", "            D    D    D            ", "            D    D    D            ", "            D    D    D            ", "            D    D    D            ", "            D    D    D            ", "            D    D    D            ", "            D    D    D            ", "           DD    D    DD           ", "           D     D     D           ", "           D     D     D           ", "           D   F D F   D           ", "           D     C     D           ", "           D     C     D           ", "           D     C     D           ", "           D     C     D           ", "          DD     C     DD          ", "          D      C      D          ", "          D      C      D          ", "          D      C      D          ", "         DD      C      DD         ", "         D     FDCDF     D         ", "         D      DCD      D         ", "        DD      DCD      DD        ", "        D       DCD       D        ", "        D       DCD       D        ", "       DD      DDCDD      DD       ", "       D       D C D       D       ", "       D       D C D       D       ", "      DD       D C D       DD      ", "      D        D C D        D      ", "     DD XX     XDCDX     XX DD     ", "    DD  XI     XDCDX     IX  DD    ", " DDDD   XX     XDCDX     XX   DDDD ", "FFFD    XXFFFFFDDDDDFFFFFXX    DFFF", "AAAAAAAAXX  AAAXXXXXAAA  XXAAAAAAAA")
                .aisle("                FFF                ", "                 E                 ", "                 E                 ", "                 E                 ", "                 E                 ", "                 E                 ", "               F   F               ", "              E     E              ", "              E     E              ", "              E     E              ", "              E     E              ", "              E     E              ", "              E     E              ", "              E     E              ", "              E     E              ", "              E     E              ", "                                   ", "                                   ", "                FFF                ", "                                   ", "                                   ", "            H         H            ", "                                   ", "                                   ", "                                   ", "                                   ", "                                   ", "                                   ", "                FFF                ", "                                   ", "                                   ", "                                   ", "                                   ", "       H                   H       ", "                                   ", "                                   ", "                                   ", "                                   ", "                XXX                ", "                XXX                ", "  D             XXX             D  ", " FFF        FFFFFFFFFFF        FFF ", " AAAAAAAAAAAAAAAAAAAAAAAAAAAAAAAAA ")
                .aisle("                                   ", "                                   ", "                                   ", "                                   ", "                                   ", "                                   ", "                FFF                ", "                                   ", "                                   ", "                                   ", "                                   ", "                                   ", "                                   ", "                                   ", "             E       E             ", "             E       E             ", "             E       E             ", "             E       E             ", "             E       E             ", "             E       E             ", "             E       E             ", "            HE       EH            ", "             E       E             ", "             E       E             ", "                                   ", "                                   ", "                                   ", "                                   ", "                                   ", "                                   ", "                                   ", "                                   ", "                                   ", "        H                 H        ", "                                   ", "                                   ", "                                   ", "                                   ", "                                   ", "                                   ", "  D                             D  ", " FFF         FFFFFFFFF         FFF ", " AAAAAAAAAAAAAAAAAAAAAAAAAAAAAAAAA ")
                .aisle("                                   ", "                                   ", "                                   ", "                                   ", "                                   ", "                                   ", "                                   ", "                E E                ", "               DE ED               ", "               DE ED               ", "               DE ED               ", "               DE ED               ", "               DE ED               ", "               DE ED               ", "               DE ED               ", "               DE ED               ", "                                   ", "                                   ", "                                   ", "                                   ", "                                   ", "             HH     HH             ", "            E         E            ", "            E         E            ", "            E         E            ", "            E         E            ", "            E         E            ", "            E         E            ", "                                   ", "                                   ", "                                   ", "                                   ", "                                   ", "        H                 H        ", "                                   ", "                                   ", "                                   ", "                                   ", "                                   ", "                                   ", "  D                             D  ", " FFF          FFFFFFF          FFF ", " AAAAAAAAAAAAAAAAAAAAAAAAAAAAAAAAA ")
                .aisle("                                   ", "                                   ", "                                   ", "                                   ", "                                   ", "                                   ", "                                   ", "                                   ", "                                   ", "                                   ", "                                   ", "                                   ", "                                   ", "                                   ", "                E E                ", "               DE ED               ", "               DE ED               ", "               DE ED               ", "               DE ED               ", "               DE ED               ", "               DE ED               ", "               DE ED               ", "               DE ED               ", "               DE ED               ", "                                   ", "                                   ", "           E           E           ", "           E           E           ", "           E           E           ", "           E           E           ", "           E           E           ", "                                   ", "                                   ", "         H               H         ", "                                   ", "                                   ", "                                   ", "                                   ", "                                   ", "                                   ", "   D                           D   ", "  FFF          F F F          FFF  ", "  AAAAAAAAAAAAA     AAAAAAAAAAAAA  ")
                .aisle("                                   ", "                                   ", "                                   ", "                                   ", "                                   ", "                                   ", "                                   ", "                                   ", "                                   ", "                                   ", "                                   ", "                                   ", "                                   ", "                                   ", "                                   ", "                                   ", "                                   ", "                                   ", "                                   ", "                                   ", "                                   ", "                                   ", "                E E                ", "               DE ED               ", "               DE ED               ", "               DE ED               ", "               DE ED               ", "               DE ED               ", "          E             E          ", "          E             E          ", "          E             E          ", "          E             E          ", "          E             E          ", "         HE             EH         ", "                                   ", "                                   ", "                                   ", "                                   ", "                                   ", "                                   ", "   D                           D   ", "  FFF          F F F          FFF  ", "  AAAAAAAAAAAAA     AAAAAAAAAAAAA  ")
                .aisle("                                   ", "                                   ", "                                   ", "                                   ", "                                   ", "                                   ", "                                   ", "                                   ", "                                   ", "                                   ", "                                   ", "                                   ", "                                   ", "                                   ", "                                   ", "                                   ", "                                   ", "                                   ", "                                   ", "                                   ", "                                   ", "                                   ", "                                   ", "                                   ", "                                   ", "                                   ", "                E E                ", "               DE ED               ", "               DE ED               ", "               DE ED               ", "               DE ED               ", "                                   ", "         E               E         ", "         EHH           HHE         ", "         E               E         ", "         E               E         ", "         E               E         ", "         E               E         ", "         E     X X X     E         ", "         E     I I I     E         ", "         E     X X X     E         ", "   FF    E     X X X     E    FF   ", "   AAAAAAAAAAAAX X XAAAAAAAAAAAA   ")
                .aisle("                                   ", "                                   ", "                                   ", "                                   ", "                                   ", "                                   ", "                                   ", "                                   ", "                                   ", "                                   ", "                                   ", "                                   ", "                                   ", "                                   ", "                                   ", "                                   ", "                                   ", "                                   ", "                                   ", "                                   ", "                                   ", "                                   ", "                                   ", "                                   ", "                                   ", "                                   ", "                                   ", "                                   ", "                                   ", "                E E                ", "               DE ED               ", "               DE ED               ", "               DE ED               ", "            HH DE ED HH            ", "                                   ", "                                   ", "                                   ", "                                   ", "               X X X               ", "               X X X               ", "               X X X               ", "               X X X               ", "   AAAAAAAAAAAAX X XAAAAAAAAAAAA   ")
                .aisle("                                   ", "                                   ", "                                   ", "                                   ", "                                   ", "                                   ", "                                   ", "                                   ", "                                   ", "                                   ", "                                   ", "                                   ", "                                   ", "                                   ", "                                   ", "                                   ", "                                   ", "                                   ", "                                   ", "                                   ", "                                   ", "                                   ", "                                   ", "                                   ", "                                   ", "                                   ", "                                   ", "                                   ", "                                   ", "                                   ", "                                   ", "                                   ", "                E E                ", "              HDE EDH              ", "               DE ED               ", "               DE ED               ", "               DE ED               ", "                                   ", "                                   ", "                                   ", "                                   ", "                                   ", "    AAAAAAAAAAAAAAAAAAAAAAAAAAA    ")
                .aisle("                                   ", "                                   ", "                                   ", "                                   ", "                                   ", "                                   ", "                                   ", "                                   ", "                                   ", "                                   ", "                                   ", "                                   ", "                                   ", "                                   ", "                                   ", "                                   ", "                                   ", "                                   ", "                                   ", "                                   ", "                                   ", "                                   ", "                                   ", "                                   ", "                                   ", "                                   ", "                                   ", "                                   ", "                                   ", "                                   ", "                                   ", "                                   ", "                                   ", "                                   ", "                                   ", "                E E                ", "               DE ED               ", "               DE ED               ", "               DE ED               ", "                                   ", "                                   ", "                                   ", "     AAAAAAAAAAAAAAAAAAAAAAAAA     ")
                .aisle("                                   ", "                                   ", "                                   ", "                                   ", "                                   ", "                                   ", "                                   ", "                                   ", "                                   ", "                                   ", "                                   ", "                                   ", "                                   ", "                                   ", "                                   ", "                                   ", "                                   ", "                                   ", "                                   ", "                                   ", "                                   ", "                                   ", "                                   ", "                                   ", "                                   ", "                                   ", "                                   ", "                                   ", "                                   ", "                                   ", "                                   ", "                                   ", "                                   ", "                                   ", "                                   ", "                                   ", "                                   ", "                E E                ", "               DE ED               ", "               DE ED               ", "                                   ", "                                   ", "      AAAAAAAAAAAAAAAAAAAAAAA      ")
                .aisle("                                   ", "                                   ", "                                   ", "                                   ", "                                   ", "                                   ", "                                   ", "                                   ", "                                   ", "                                   ", "                                   ", "                                   ", "                                   ", "                                   ", "                                   ", "                                   ", "                                   ", "                                   ", "                                   ", "                                   ", "                                   ", "                                   ", "                                   ", "                                   ", "                                   ", "                                   ", "                                   ", "                                   ", "                                   ", "                                   ", "                                   ", "                                   ", "                                   ", "                                   ", "                                   ", "                                   ", "                                   ", "                                   ", "                E E                ", "               DE ED               ", "               D   D               ", "         FFF           FFF         ", "       AAAAAAAAAAAAAAAAAAAAA       ")
                .aisle("                                   ", "                                   ", "                                   ", "                                   ", "                                   ", "                                   ", "                                   ", "                                   ", "                                   ", "                                   ", "                                   ", "                                   ", "                                   ", "                                   ", "                                   ", "                                   ", "                                   ", "                                   ", "                                   ", "                                   ", "                                   ", "                                   ", "                                   ", "                                   ", "                                   ", "                                   ", "                                   ", "                                   ", "                                   ", "                                   ", "                                   ", "                                   ", "                                   ", "                                   ", "                                   ", "                                   ", "                                   ", "                                   ", "                                   ", "                E E                ", "          DD   DE ED   DD          ", "         FFFFFFD   DFFFFFF         ", "        AAAAAAAAAAAAAAAAAAA        ")
                .aisle("                                   ", "                                   ", "                                   ", "                                   ", "                                   ", "                                   ", "                                   ", "                                   ", "                                   ", "                                   ", "                                   ", "                                   ", "                                   ", "                                   ", "                                   ", "                                   ", "                                   ", "                                   ", "                                   ", "                                   ", "                                   ", "                                   ", "                                   ", "                                   ", "                                   ", "                                   ", "                                   ", "                                   ", "                                   ", "                                   ", "                                   ", "                                   ", "                                   ", "                                   ", "                                   ", "                                   ", "                                   ", "                                   ", "                                   ", "                                   ", "            DDDDE EDDDD            ", "          FFFFFFF FFFFFFF          ", "          AAAAAAAAAAAAAAA          ")
                .aisle("                                   ", "                                   ", "                                   ", "                                   ", "                                   ", "                                   ", "                                   ", "                                   ", "                                   ", "                                   ", "                                   ", "                                   ", "                                   ", "                                   ", "                                   ", "                                   ", "                                   ", "                                   ", "                                   ", "                                   ", "                                   ", "                                   ", "                                   ", "                                   ", "                                   ", "                                   ", "                                   ", "                                   ", "                                   ", "                                   ", "                                   ", "                                   ", "                                   ", "                                   ", "                                   ", "                                   ", "                                   ", "                                   ", "                                   ", "                                   ", "               D   D               ", "            FFFFF FFFFF            ", "            AAAAAAAAAAA            ")
                .aisle("                                   ", "                                   ", "                                   ", "                                   ", "                                   ", "                                   ", "                                   ", "                                   ", "                                   ", "                                   ", "                                   ", "                                   ", "                                   ", "                                   ", "                                   ", "                                   ", "                                   ", "                                   ", "                                   ", "                                   ", "                                   ", "                                   ", "                                   ", "                                   ", "                                   ", "                                   ", "                                   ", "                                   ", "                                   ", "                                   ", "                                   ", "                                   ", "                                   ", "                                   ", "                                   ", "                                   ", "                                   ", "                                   ", "                                   ", "                                   ", "                                   ", "               FF FF               ", "               AAAAA               ")
            .where("~", controller.self())
			.where("D", <blockstate:contenttweaker:base_casing>)
            .where(" ", CTPredicate.getAir()) // Anything
			.where("E", <blockstate:minecraft:stone>)
			.where("X", <blockstate:minecraft:glass>)
            .where("F", <blockstate:minecraft:dirt>)
            .where("-", <blockstate:contenttweaker:space_elevator_cable>)
            .where("H", <blockstate:minecraft:iron_block>)
            .where("C", <blockstate:minecraft:iron_block>)
            .where("I", <blockstate:minecraft:iron_block>)
            .where("A", CTPredicate.states(<blockstate:contenttweaker:concrete_floor>)
            
                                      | CTPredicate.abilities(<mte_ability:IMPORT_ITEMS>).setMinGlobalLimited(1).setPreviewCount(1) // There is at least one IMPORT_ITEMS bus. JEI preview shows only one.
                                      | CTPredicate.abilities(<mte_ability:EXPORT_ITEMS>).setMinGlobalLimited(1).setPreviewCount(1)
                                      | CTPredicate.abilities(<mte_ability:IMPORT_FLUIDS>).setMinGlobalLimited(1).setPreviewCount(1)
                                      | CTPredicate.abilities(<mte_ability:EXPORT_FLUIDS>).setMinGlobalLimited(1).setPreviewCount(1)
                                      | CTPredicate.abilities(<mte_ability:INPUT_ENERGY>).setMinGlobalLimited(1).setPreviewCount(1)
            )              
            .build();
    } as IPatternBuilderFunction)
	    .withRecipeMap(
		FactoryRecipeMap.start("space_elevator")
                        .minFluidInputs(1)
                        .maxFluidInputs(1)
                        .minFluidOutputs(1)
                        .maxFluidOutputs(1)
                        .minInputs(1)
						.maxInputs(1)
						.minOutputs(1)
                        .maxOutputs(4)
                        .build())
		.withBaseTexture(<contenttweaker:station_casing>.asBlock().definition.getStateFromMeta(1))
		.buildAndRegister();